

# 11章　例外とエラー処理
例外処理は、想定していない例外的なケースのための処理である。  
想定しているエラーとそうでないエラーは境界が曖昧ではある。  

## 11.1　Errorオブジェクト
JavaScriptには組み込みのErrorオブジェクトがある。 
Errorのインスタンスの生成時にエラーメッセージを指定できる。  
``const err = new Error('メールアドレスの形式が正しくありません');``

```js
const email = "janedoe.com";

const validatedEmail = validateEmail(email);
if(validatedEmail instanceof Error) {
  console.error(validatedEmail.message);
} else {
  console.log(`正しい形式のアドレスです: ${validatedEmail}`);
}

function validateEmail(email) {
  return email.match(/@/) ?
    email :
    new Error(`無効なメールアドレスです：${email}`);
}
```

## 11.2　例外処理（try...catch）
例外処理にはtry...catch文を使う。  
下の例では、JavaScriptの処理系が生成したエラーをキャッチしている。  
```js
const email = null;

function validateEmail(email) {
  return email.match(/@/) ?
    email :
    new Error(`無効なメールアドレスです：${email}`);
}

try {
  const validatedEmail = validateEmail(email);
  console.log(validatedEmail);
  if(validatedEmail instanceof Error) {
    console.error(validatedEmail.message);
} else {
  console.log(`正しい形式のアドレスです: ${validatedEmail}`);
}
} catch (err) {
  console.error(`エラー：${err.message}`);
}
```

## 11.3　例外のスロー
例外を明示的にスローすることもできる。  
スローには任意の値を取ることもできるが、慣例でErrorオブジェクトのインスタンスをスローするのが一般的である。これはcatchブロックでも同様である。  

```js
function billPay(amount, payee, account) {
  if(amount > account.balance) // 支払額が残高より大きい
    throw new Error("残高不足");
  account.transfer(payee, amount); // payeeにamountを支払う
}
```

## 11.4　例外処理とコールスタック
コールスタックは、多重の関数呼び出しがあった際に情報を保存しておく領域のことである。  
コールスタックはデバックに役に立つ。JavaScriptにおいては、Errorのインスタンスのstackプロパティによって、コールスタックの文字列を見ることができる。  
```js
// 関数cはエラーをスローする
// aからerr.stackすると、b,cと遡る
// dからerr.stackすると、直接cに遡る
function a() {
  console.log('a: bを呼び出す前');
  b();
  console.log('a: 終了');
}
function b() {
  console.log('b: cを呼び出す前');
  c();
  console.log('b: 終了');
}
function c() {
  console.log('c: エラーをスローする');
  throw new Error('c error');
  console.log('c: 終了');
}
function d() {
  console.log('d: cを呼び出す前');
  c();
  console.log('d: 終了');
}
try {
  a();
} catch(err) {
  console.log("---- a呼び出し後のerr.stack ----");
  console.log(err.stack);
  console.log("---- 終わり -----");
}
try {
  d();
} catch(err) {
  console.log("---- d呼び出し後のerr.stack ----");
  console.log(err.stack);
  console.log("---- 終わり ----");
}
```
## 11.5　try...catch...finally
finallyはエラーの有無に関わらずに必ず処理をすることができる。  
tryブロックで何らかのリソース(HTTP経由の接続やファイル)に関係する処理を書く場合は、finallyブロックでリソースを解放する。  
```js
try {
  console.log("1行目実行中...");
  throw new Error("エラー1"); /* この行をコメントにすると下の行が実行される */
  console.log("throwが実行されると、この行は実行されない...");
} catch(err) {
  console.log("エラーが起こった...");
} finally {
  console.log("finallyの中のこの行はいつも実行される");
  console.log("リソースの解放をここで行う");
}

/* 実行結果
1行目実行中...
エラーが起こった...
finallyの中のこの行はいつも実行される
リソースの解放をここで行う
*/
```

## 11.6　例外処理は例外に限る
あらかじめ想定できるエラーは、通常のフロー制御を使って対処する。  
例外処理にはスタックをさかのぼるというコストがかかる。例外をスローしたら必ずキャッチしなければならない。  
例外処理は、本当に予測できない例外的な事態に備えるものとしてとっておくのがよい。  